Workbook
Name ListaInsumos: 'Registro de Insumos'!$D$18:$D$1993
Name SíntesePrecificação: 'Síntese de Precificação'!$B$7:$J$333
Name ListaInsumos: 'Precificação Produto | Custo Co'!$D$104:$D$1993
Name ListaInsumos: 'Precificação Serviços | Custo D'!$D$19:$D$1993
Name ListaInsumos: 'Base de Salários'!$D$18:$D$1989
Name ListaInsumos: 'Precificação Produto | Custo De'!$D$19:$D$1993

Sheet Menu
B2: Precificação
B9: KL Engenharia

Sheet Gastos Fixos
C1: Gastos Fixos
C9: Item | D9: Valor | G9: Faturamento Estimado | H9: =9378337.24 + 722090.73 -> 10100428
G10: Soma das Despesas | H10: =SUMIF(D14:D1248,"<>",E14:E1248) -> 2028424
D11: =IFERROR(IF(COUNTIF(teste!$A$7:$D1248,D10)>=1,"-","--"),"") -> -- | E11: =IFERROR(IF(COUNTIF(teste!$A$7:$D1248,H10)>=1,"-","--"),"") -> -- | F11: =IFERROR(IF(COUNTIF(teste!$A$7:$D1248,I10)>=1,"-","--"),"") -> -- | G11: % Fixos vs Faturamento | H11: =H10/H9 -> 0.20082555
C13: ID | D13: Item | E13: Valor
C14: 1 | D14: Despesas Administrativas | E14: 1461373.8
C15: 2 | D15: Despesas Financeiras | E15: 4468.34
C16: 3 | D16: Outras Despesas Operacionais | E16: 562581.93

Sheet Manual de Uso
B1: Manual de Uso
B7: Obs 1: | C7: Para melhor visualização da planilha de ferramenta estratégica, é recomendado que o tamanho da página ("zoom") seja ou 75% ou 90%. Para alterar isso, basta mudar no número que está depois do simbolo de impressão e antes do símbolo de cifrão.
B8: Obs 2: | C8: A página "Validação de Dados" é oculta, caso seja necessário mudanças, basta clicar nas três barrinhas no canto inferior esquerdo e selecionar a aba
B9: Obs 3: | C9: Para selecionar a data na página "Registro", basta clilcar duas vezes na célula e selecionar a data desejada
B10: Obs 4: | C10: Para registrar vários itens de uma vez só, basta escrever uma linha de registros e puxar para baixo
B11: Obs 5: | C11: Se o valor do item a ser registrado não for informado, o registro desse item não será feito
B12: Obs 6: | C12: O botão de apagar na aba "Registros" apaga os últimos itens registrados na aba "Base de Dados" e reescreve eles na aba "Registros"
B13: Obs 7: | C13: Sempre que for ADICIONAR/RETIRAR um item do plano de contas, lembrar que Adicionar/Retirar esse item da "Tabela de Validações" da aba de "Validações de Dados" (sem isso, esse item ainda irá aparecer no registro)
B14: Obs 8: | C14: NÃO deletar e nem adicionar colunas ou linhas, principalmente na aba de "Registros" e "Indicadores" - Essas alterações podem afetar o funcionamento da planilha. Se necessário, oculte linhas ou células
B15: Obs 9: | C15: Caso queiram buscar algum dado na "Base de Dados", basta clicar em "Ctrl + F" e digitar o valor que queira buscar ou usar os Filtros
B16: Obs 10: | C16: Na aba "Base de Dados", é possível filtrar as informações pela informação desejada, basta clicar no funil ao lado da informação desejada
B18: Trocar as instruções de acordo com o projeto, isso é só um template!!!

Sheet Gastos Variáveis
B1: Gastos Variáveis
C9: Taxa | D9: Porcentagem | G9: Soma das Porcentagens | H9: =SUMIF(D14:D1246,"<>",E14:E1246) -> 0.0094
D11: =IFERROR(IF(COUNTIF(teste!$A$7:$D1246,D10)>=1,"-","--"),"") -> -- | E11: =IFERROR(IF(COUNTIF(teste!$A$7:$D1246,H9)>=1,"-","--"),"") -> -- | F11: =IFERROR(IF(COUNTIF(teste!$A$7:$D1246,I10)>=1,"-","--"),"") -> --
C13: ID | D13: Item | E13: Valor
C14: 1 | D14: Impostos | E14: 0.0094

Sheet Registro de Insumos
D1: Registro de Insumos
A6: 0 | C6: SEERRO(FILTER( 'Base de Dados'!A7:Q; ('Base de Dados'!A7:A = C16) + (C16 = ""); ('Base de Dados'!E7:E = C17) + (C17 = ""); ('Base de Dados'!C7:C = C18) + (C18 = ""); ('Base de Dados'!I7:I = C19) + (C19 = ""); ('Base de Dados'!D7:D = C20) + (C20 = ""));) | D6: FILTER(A10:L14; (D10:D14 <> "") * (E10:E14 <> "") * (F10:F14 <> "") * (G10:G14 <> "") * (I10:I14 <> "") * (J10:J14 <> ""))
B8: Editar | C8: Registro | AD8: =COUNTA($U$11:$U$15) -> 1
B9: Registro | C9: Item | D9: Unidade de Medida | E9: Quantidade Referência | F9: Custo Referência | V9: ID | W9: Data | X9: Item | Y9: Fluxo | Z9: Tipo | AA9: Centro | AB9: Descrição | AC9: Forma de pagamento | AD9: Valor Total | AE9: Parcelas | AF9: Desconto
U10: =U11 -> #N/A | V10: =V11 | W10: =W11 | X10: =X11 | Y10: =Y11 | Z10: =Z11 | AA10: =AA11 | AB10: =AB11 | ... AF10: =AF11
U11: =IFERROR(__xludf.DUMMYFUNCTION("FILTER(A10:L14, (D10:D14 <> """") * (E10:E14 <> """") * (F10:F14 <> """") * (G10:G14 <> """"))"),"#N/A") -> #N/A
C17: ID | D17: Item | E17: Unidade | F17: Quantidade Ref | G17: Custo Ref
C18: 0 F202AC-40/0,03 | D18: DR 2P 40A.30MA ABB | E18: Unidade | F18: 1 | G18: 0
C19: 10289152 | D19: BORNE BTWP 16-AZ 750 V | E19: Unidade | F19: 1 | G19: 6.43
C20: 11898941 | D20: CHAVE SECCIONADORA ROTATIVA MSW 80A 3 POLOS COM MANOPLA VERMELHA / AMARELA PARA MONTAGEM EM BASE ATE | E20: Unidade | F20: 1 | G20: 221.75
C21: 12486844 | D21: MINICONTATOR AZ CWCA0-31-00V26 190V 50HZ/220V 60HZ AZUL | E21: Unidade | F21: 1 | G21: 32.55
C22: 12486847 | D22: MINICONTATOR AZ CWCA0-40-00V26 190V 50HZ/220V 60HZ AZUL | E22: Unidade | F22: 1 | G22: 32.55
C23: 12499384 | D23: BLOCO CONTATO AUXILIAR FRONTAL BFCA 3NA+1NF COM PARAFUSO UI MAX=660/690 VOLTS AZUL MINICONTATOR CWCA | E23: Unidade | F23: 1 | G23: 24.59
C24: 12499385 | D24: BLOCO CONTATO AUXILIAR FRONTAL BFCA 4NA COM PARAFUSO UI MAX=660/690 VOLTS AZUL MINICONTATOR CWCA0 | E24: Unidade | F24: 1 | G24: 24.59
C25: 12775000 | D25: BLOCO DE CONTATO BC-1R PARA DISJUNTOR CAIXA MOLDADA AGW50-250 | E25: Unidade | F25: 1 | G25: 53.4
C26: 12775002 | D26: BLOCO DE ALARME AL-1R PARA DISJUNTOR CAIXA MOLDADA AGW50-250 | E26: Unidade | F26: 1 | G26: 59.05
C27: 12775054 | D27: BOBINA DE DISPARO BD 110-220 VCA/VCC PARA DISJUNTOR CAIXA MOLDADA AGW400-800 | E27: Unidade | F27: 1 | G27: 174.65
C28: 12775103 | D28: DISJUNTOR EM CAIXA MOLDADA AGW250 30 KA (380 VCA) MAGNETICO E TERMICO FIXO 125 A 3 POLOS | E28: Unidade | F28: 1 | G28: 220.19
C29: 12775150 | D29: DISJUNTOR EM CAIXA MOLDADA AGW400 42 KA (380 VCA) MAGNETICO E TERMICO FIXO 350 A 3 POLOS | E29: Unidade | F29: 1 | G29: 699.22
C30: 12778357 | D30: MANOPLA ROTATIVA MR 469 MM CINZA PARA DISJUNTOR CAIXA MOLDADA AGW250 | E30: Unidade | F30: 1 | G30: 205.75
... C74: 7595 | D74: TECLADO S/FIO KIT + MOUSE S/FIO USB NANO REF. MK-295 LOGITECH | E74: Unidade | F74: 1 | G74: 269.9
C75: 01.05.10.0023 | D75: CH ALLEN T 6MM /SATA | E75: Unidade | F75: 1 | G75: 25.98
C76: 01.05.10.0024 | D76: CH ALLEN T 5MM /SATA | E76: Unidade | F76: 1 | G76: 20.83
C77: 10413668 | D77: CMS2-15 LUVA CRISTAL | E77: Unidade | F77: 1 | G77: 164.3
C78: 10415378 | D78: CMS2/3-18 LUVA CRISTAL | E78: Unidade | F78: 1 | G78: 0.77
C79: 110083 | D79: CADEADO LATAO 50MM PADO | E79: Unidade | F79: 1 | G79: 48
C80: 111764 | D80: SPRAY PINTURA 400ML AZUL MOTOR RADCOLOR | E80: Unidade | F80: 1 | G80: 17
C81: 112490 | D81: FITA DUPLA FACE TRANSP 19MM X 2M ADERMAX ADERE | E81: Unidade | F81: 1 | G81: 15
C82: 113549 | D82: PRIMER MANTA BASE DGUA 1LT PRODESIVO/WADIMEX | E82: Unidade | F82: 1 | G82: 15
C83: 113780 | D83: PINO JUNCAO MACHO 2P+T 10AMP PRETO/BRANCO TRAMONTI | E83: Unidade | F83: 1 | G83: 8.5
C84: 115458 | D84: MASSA PLASTICA BRANCA 400G IBERE | E84: Unidade | F84: 1 | G84: 19.5
C85: 115523 | D85: PARAF MITOFIX 4.5 X 40 BELENUS/CISER | E85: Unidade | F85: 1 | G85: 0.3
C86: 116079 | D86: PARAF ROSCA SOBERBA C/SEXT ZINC 1/4 X 60MM CISER | E86: Unidade | F86: 1 | G86: 0.9
C87: 116292 | D87: DISCO CORTE C/DEPRESSAO 9 X 1/8 X 7/8 CARBORUNDUM | E87: Unidade | F87: 1 | G87: 22
C88: 116322 | D88: FITA CREPE 48MM X 50M R-427 ADERE | E88: Unidade | F88: 1 | G88: 14
... C164: 601291 | D164: CADEADO PORTA DE ENROLAR TETRA 17500 DOVALE | E164: Unidade | F164: 1 | G164: 85
C165: 06012A80E2 | D165: LIXADEIRA DE PALMA GSS 140 A 220 W 220 V | E165: Unidade | F165: 1 | G165: 317.22
C166: 601305 | D166: PASSA FIO ALMA DE ACO 10 MT CORTAG | E166: Unidade | F166: 1 | G166: 27.5
C167: 601553 | D167: TRENA ACO C/TRAVA 3MT REF KTS12 STARRETT | E167: Unidade | F167: 1 | G167: 15
C168: 601758 | D168: ABRACADEIRA DE NYLON PRETA 4.8 X 200MM PARAMAX | E168: Unidade | F168: 1 | G168: 12
...

Sheet Painel de Visualização
B1: Painel de Visualização
B7: Data Inicial | C7: 45474 | L7: Ano e Mês | M7: Entrada | N7: Saída | O7: Lucro Líquido | P7: Fluxo de Caixa Acumulado | Q7: Custos Fixos | R7: Custos Variáveis | S7: Despesas | T7: Investimentos | U7: Inadimplência | V7: Runway | W7: Margem de Contribuição | X7: Breakeven | Y7: Margem Líquida | Z7: Faturamento | AD7: {=TRANSPOSE(B28:B554)} -> Ensaio de Casal | AE7: Ensaio simples | AF7: Ensaio de 15 anos | AG7: Ensaio de Formatura | AH7: Ensaio de Noivos
B8: Data Final | C8: 45627 | L8: =IFERROR(__xludf.DUMMYFUNCTION("FILTER(Indicadores!D27:R554,Indicadores!D27:D554>=C7,Indicadores!D27:D554<=C8)"),45474.0) -> 45474 | M8: =IFERROR(__xludf.DUMMYFUNCTION("""COMPUTED_VALUE"""),"#N/A") -> #N/A | N8: =IFERROR(__xludf.DUMMYFUNCTION("""COMPUTED_VALUE"""),"#N/A") -> #N/A | O8: =IFERROR(__xludf.DUMMYFUNCTION("""COMPUTED_VALUE"""),"#N/A") -> #N/A | P8: =IFERROR(__xludf.DUMMYFUNCTION("""COMPUTED_VALUE"""),"#N/A") -> #N/A | Q8: =IFERROR(__xludf.DUMMYFUNCTION("""COMPUTED_VALUE"""),"#N/A") -> #N/A | R8: =IFERROR(__xludf.DUMMYFUNCTION("""COMPUTED_VALUE"""),"#N/A") -> #N/A | S8: =IFERROR(__xludf.DUMMYFUNCTION("""COMPUTED_VALUE"""),"#N/A") -> #N/A | T8: =IFERROR(__xludf.DUMMYFUNCTION("""COMPUTED_VALUE"""),"#N/A") -> #N/A | U8: =IFERROR(__xludf.DUMMYFUNCTION("""COMPUTED_VALUE"""),"#N/A") -> #N/A | V8: =IFERROR(__xludf.DUMMYFUNCTION("""COMPUTED_VALUE"""),0.0) -> 0 | W8: =IFERROR(__xludf.DUMMYFUNCTION("""COMPUTED_VALUE"""),0.0) -> 0 | X8: =IFERROR(__xludf.DUMMYFUNCTION("""COMPUTED_VALUE"""),0.0) -> 0 | Y8: =IFERROR(__xludf.DUMMYFUNCTION("""COMPUTED_VALUE"""),0.0) -> 0 | Z8: =IFERROR(__xludf.DUMMYFUNCTION("""COMPUTED_VALUE"""),"#N/A") -> #N/A | AD8: =IFERROR(__xludf.DUMMYFUNCTION("FILTER('Base de Dados'!$M$7:$M554,'Base de Dados'!$B$7:$B554>=$C$7,'Base de Dados'!$B$7:$B554<=$C$8,'Base de Dados'!$D$7:$D554=AD$7,'Base de Dados'!$C$7:$C554=""Sim"")"),"#REF!") -> #REF! | AE8: =IFERROR(__xludf.DUMMYFUNCTION("FILTER('Base de Dados'!$M$7:$M554,'Base de Dados'!$B$7:$B554>=$C$7,'Base de Dados'!$B$7:$B554<=$C$8,'Base de Dados'!$D$7:$D554=AE$7,'Base de Dados'!$C$7:$C554=""Sim"")"),"#REF!") -> #REF! | AF8: =IFERROR(__xludf.DUMMYFUNCTION("FILTER('Base de Dados'!$M$7:$M554,'Base de Dados'!$B$7:$B554>=$C$7,'Base de Dados'!$B$7:$B554<=$C$8,'Base de Dados'!$D$7:$D554=AF$7,'Base de Dados'!$C$7:$C554=""Sim"")"),"#REF!") -> #REF! | AG8: =IFERROR(__xludf.DUMMYFUNCTION("FILTER('Base de Dados'!$M$7:$M554,'Base de Dados'!$B$7:$B554>=$C$7,'Base de Dados'!$B$7:$B554<=$C$8,'Base de Dados'!$D$7:$D554=AG$7,'Base de Dados'!$C$7:$C554=""Sim"")"),"#REF!") -> #REF! | AH8: =IFERROR(__xludf.DUMMYFUNCTION("FILTER('Base de Dados'!$M$7:$M554,'Base de Dados'!$B$7:$B554>=$C$7,'Base de Dados'!$B$7:$B554<=$C$8,'Base de Dados'!$D$7:$D554=AH$7,'Base de Dados'!$C$7:$C554=""Sim"")"),"#REF!") -> #REF!
L9: =IFERROR(__xludf.DUMMYFUNCTION("""COMPUTED_VALUE"""),45505.0) -> 45505 | M9: =IFERROR(__xludf.DUMMYFUNCTION("""COMPUTED_VALUE"""),"#N/A") -> #N/A | N9: =IFERROR(__xludf.DUMMYFUNCTION("""COMPUTED_VALUE"""),"#N/A") -> #N/A | O9: =IFERROR(__xludf.DUMMYFUNCTION("""COMPUTED_VALUE"""),"#N/A") -> #N/A | P9: =IFERROR(__xludf.DUMMYFUNCTION("""COMPUTED_VALUE"""),"#N/A") -> #N/A | Q9: =IFERROR(__xludf.DUMMYFUNCTION("""COMPUTED_VALUE"""),"#N/A") -> #N/A | R9: =IFERROR(__xludf.DUMMYFUNCTION("""COMPUTED_VALUE"""),"#N/A") -> #N/A | S9: =IFERROR(__xludf.DUMMYFUNCTION("""COMPUTED_VALUE"""),"#N/A") -> #N/A | T9: =IFERROR(__xludf.DUMMYFUNCTION("""COMPUTED_VALUE"""),"#N/A") -> #N/A | U9: =IFERROR(__xludf.DUMMYFUNCTION("""COMPUTED_VALUE"""),"#N/A") -> #N/A | V9: =IFERROR(__xludf.DUMMYFUNCTION("""COMPUTED_VALUE"""),0.0) -> 0 | W9: =IFERROR(__xludf.DUMMYFUNCTION("""COMPUTED_VALUE"""),0.0) -> 0 | X9: =IFERROR(__xludf.DUMMYFUNCTION("""COMPUTED_VALUE"""),0.0) -> 0 | Y9: =IFERROR(__xludf.DUMMYFUNCTION("""COMPUTED_VALUE"""),0.0) -> 0 | Z9: =IFERROR(__xludf.DUMMYFUNCTION("""COMPUTED_VALUE"""),"#N/A") -> #N/A
B10: Entradas Efetivas | L10: =IFERROR(__xludf.DUMMYFUNCTION("""COMPUTED_VALUE"""),45536.0) -> 45536 | M10: =IFERROR(__xludf.DUMMYFUNCTION("""COMPUTED_VALUE"""),"#N/A") -> #N/A | N10: =IFERROR(__xludf.DUMMYFUNCTION("""COMPUTED_VALUE"""),"#N/A") -> #N/A | O10: =IFERROR(__xludf.DUMMYFUNCTION("""COMPUTED_VALUE"""),"#N/A") -> #N/A | P10: =IFERROR(__xludf.DUMMYFUNCTION("""COMPUTED_VALUE"""),"#N/A") -> #N/A | Q10: =IFERROR(__xludf.DUMMYFUNCTION("""COMPUTED_VALUE"""),"#N/A") -> #N/A | R10: =IFERROR(__xludf.DUMMYFUNCTION("""COMPUTED_VALUE"""),"#N/A") -> #N/A | S10: =IFERROR(__xludf.DUMMYFUNCTION("""COMPUTED_VALUE"""),"#N/A") -> #N/A | T10: =IFERROR(__xludf.DUMMYFUNCTION("""COMPUTED_VALUE"""),"#N/A") -> #N/A | U10: =IFERROR(__xludf.DUMMYFUNCTION("""COMPUTED_VALUE"""),"#N/A") -> #N/A | V10: =IFERROR(__xludf.DUMMYFUNCTION("""COMPUTED_VALUE"""),0.0) -> 0 | W10: =IFERROR(__xludf.DUMMYFUNCTION("""COMPUTED_VALUE"""),0.0) -> 0 | X10: =IFERROR(__xludf.DUMMYFUNCTION("""COMPUTED_VALUE"""),0.0) -> 0 | Y10: =IFERROR(__xludf.DUMMYFUNCTION("""COMPUTED_VALUE"""),0.0) -> 0 | Z10: =IFERROR(__xludf.DUMMYFUNCTION("""COMPUTED_VALUE"""),"#N/A") -> #N/A
L11: =IFERROR(__xludf.DUMMYFUNCTION("""COMPUTED_VALUE"""),45566.0) -> 45566 | M11: =IFERROR(__xludf.DUMMYFUNCTION("""COMPUTED_VALUE"""),"#N/A") -> #N/A | N11: =IFERROR(__xludf.DUMMYFUNCTION("""COMPUTED_VALUE"""),"#N/A") -> #N/A | O11: =IFERROR(__xludf.DUMMYFUNCTION("""COMPUTED_VALUE"""),"#N/A") -> #N/A | P11: =IFERROR(__xludf.DUMMYFUNCTION("""COMPUTED_VALUE"""),"#N/A") -> #N/A | Q11: =IFERROR(__xludf.DUMMYFUNCTION("""COMPUTED_VALUE"""),"#N/A") -> #N/A | R11: =IFERROR(__xludf.DUMMYFUNCTION("""COMPUTED_VALUE"""),"#N/A") -> #N/A | S11: =IFERROR(__xludf.DUMMYFUNCTION("""COMPUTED_VALUE"""),"#N/A") -> #N/A | T11: =IFERROR(__xludf.DUMMYFUNCTION("""COMPUTED_VALUE"""),"#N/A") -> #N/A | U11: =IFERROR(__xludf.DUMMYFUNCTION("""COMPUTED_VALUE"""),"#N/A") -> #N/A | V11: =IFERROR(__xludf.DUMMYFUNCTION("""COMPUTED_VALUE"""),0.0) -> 0 | W11: =IFERROR(__xludf.DUMMYFUNCTION("""COMPUTED_VALUE"""),0.0) -> 0 | X11: =IFERROR(__xludf.DUMMYFUNCTION("""COMPUTED_VALUE"""),0.0) -> 0 | Y11: =IFERROR(__xludf.DUMMYFUNCTION("""COMPUTED_VALUE"""),0.0) -> 0 | Z11: =IFERROR(__xludf.DUMMYFUNCTION("""COMPUTED_VALUE"""),"#N/A") -> #N/A
B12: {=IF(C8>=C7,SUM(XLOOKUP(C7,Indicadores!$D$27:$D554,Indicadores!$E$27:$E554):XLOOKUP(C8,Indicadores!$D$27:$D554,Indicadores!$E$27:$E554)),"Insira uma Data Final maior ou igual à Data Inicial")} -> #N/A | E12: Custo Fixo | F12: Custo Variável | G12: Despesas | H12: Investimentos | I12: Inadimplência | L12: =IFERROR(__xludf.DUMMYFUNCTION("""COMPUTED_VALUE"""),45597.0) -> 45597 | M12: =IFERROR(__xludf.DUMMYFUNCTION("""COMPUTED_VALUE"""),"#N/A") -> #N/A | N12: =IFERROR(__xludf.DUMMYFUNCTION("""COMPUTED_VALUE"""),"#N/A") -> #N/A | O12: =IFERROR(__xludf.DUMMYFUNCTION("""COMPUTED_VALUE"""),"#N/A") -> #N/A | P12: =IFERROR(__xludf.DUMMYFUNCTION("""COMPUTED_VALUE"""),"#N/A") -> #N/A | Q12: =IFERROR(__xludf.DUMMYFUNCTION("""COMPUTED_VALUE"""),"#N/A") -> #N/A | R12: =IFERROR(__xludf.DUMMYFUNCTION("""COMPUTED_VALUE"""),"#N/A") -> #N/A | S12: =IFERROR(__xludf.DUMMYFUNCTION("""COMPUTED_VALUE"""),"#N/A") -> #N/A | T12: =IFERROR(__xludf.DUMMYFUNCTION("""COMPUTED_VALUE"""),"#N/A") -> #N/A | U12: =IFERROR(__xludf.DUMMYFUNCTION("""COMPUTED_VALUE"""),"#N/A") -> #N/A | V12: =IFERROR(__xludf.DUMMYFUNCTION("""COMPUTED_VALUE"""),0.0) -> 0 | W12: =IFERROR(__xludf.DUMMYFUNCTION("""COMPUTED_VALUE"""),0.0) -> 0 | X12: =IFERROR(__xludf.DUMMYFUNCTION("""COMPUTED_VALUE"""),0.0) -> 0 | Y12: =IFERROR(__xludf.DUMMYFUNCTION("""COMPUTED_VALUE"""),0.0) -> 0 | Z12: =IFERROR(__xludf.DUMMYFUNCTION("""COMPUTED_VALUE"""),"#N/A") -> #N/A
L13: =IFERROR(__xludf.DUMMYFUNCTION("""COMPUTED_VALUE"""),45627.0) -> 45627 | M13: =IFERROR(__xludf.DUMMYFUNCTION("""COMPUTED_VALUE"""),"#N/A") -> #N/A | N13: =IFERROR(__xludf.DUMMYFUNCTION("""COMPUTED_VALUE"""),"#N/A") -> #N/A | O13: =IFERROR(__xludf.DUMMYFUNCTION("""COMPUTED_VALUE"""),"#N/A") -> #N/A | P13: =IFERROR(__xludf.DUMMYFUNCTION("""COMPUTED_VALUE"""),"#N/A") -> #N/A | Q13: =IFERROR(__xludf.DUMMYFUNCTION("""COMPUTED_VALUE"""),"#N/A") -> #N/A | R13: =IFERROR(__xludf.DUMMYFUNCTION("""COMPUTED_VALUE"""),"#N/A") -> #N/A | S13: =IFERROR(__xludf.DUMMYFUNCTION("""COMPUTED_VALUE"""),"#N/A") -> #N/A | T13: =IFERROR(__xludf.DUMMYFUNCTION("""COMPUTED_VALUE"""),"#N/A") -> #N/A | U13: =IFERROR(__xludf.DUMMYFUNCTION("""COMPUTED_VALUE"""),"#N/A") -> #N/A | V13: =IFERROR(__xludf.DUMMYFUNCTION("""COMPUTED_VALUE"""),0.0) -> 0 | W13: =IFERROR(__xludf.DUMMYFUNCTION("""COMPUTED_VALUE"""),0.0) -> 0 | X13: =IFERROR(__xludf.DUMMYFUNCTION("""COMPUTED_VALUE"""),0.0) -> 0 | Y13: =IFERROR(__xludf.DUMMYFUNCTION("""COMPUTED_VALUE"""),0.0) -> 0 | Z13: =IFERROR(__xludf.DUMMYFUNCTION("""COMPUTED_VALUE"""),"#N/A") -> #N/A
E14: {=IF($C$8>=$C$7,SUM(XLOOKUP($C$7,Indicadores!$D$27:$D554,Indicadores!I$27:I554):XLOOKUP($C$8,Indicadores!$D$27:$D554,Indicadores!I$27:I554)),"Insira uma Data Final maior ou igual à Data Inicial")} -> #N/A | F14: {=IF($C$8>=$C$7,SUM(XLOOKUP($C$7,Indicadores!$D$27:$D554,Indicadores!J$27:J554):XLOOKUP($C$8,Indicadores!$D$27:$D554,Indicadores!J$27:J554)),"Insira uma Data Final maior ou igual à Data Inicial")} -> #N/A | G14: {=IF($C$8>=$C$7,SUM(XLOOKUP($C$7,Indicadores!$D$27:$D554,Indicadores!K$27:K554):XLOOKUP($C$8,Indicadores!$D$27:$D554,Indicadores!K$27:K554)),"Insira uma Data Final maior ou igual à Data Inicial")} -> #N/A | H14: {=IF($C$8>=$C$7,SUM(XLOOKUP($C$7,Indicadores!$D$27:$D554,Indicadores!L$27:L554):XLOOKUP($C$8,Indicadores!$D$27:$D554,Indicadores!L$27:L554)),"Insira uma Data Final maior ou igual à Data Inicial")} -> #N/A | I14: {=IF($C$8>=$C$7,SUM(XLOOKUP($C$7,Indicadores!$D$27:$D554,Indicadores!M$27:M554):XLOOKUP($C$8,Indicadores!$D$27:$D554,Indicadores!M$27:M554)),"Insira uma Data Final maior ou igual à Data Inicial")} -> #N/A
B15: Saídas Efetivas
B17: {=IF(C8>=C7,SUM(XLOOKUP(C7,Indicadores!$D$27:$D554,Indicadores!$F$27:$F554):XLOOKUP(C8,Indicadores!$D$27:$D554,Indicadores!$F$27:$F554)),"Insira uma Data Final maior ou igual à Data Inicial")} -> #N/A
E18: Breakeven | F18: Gasto Mensal Médio | G18: Valor Em Caixa | H18: Runway | I18: Margem Líquida
H19: {="(A partir de "&TEXT(XLOOKUP(H20,Indicadores!N27:N554,Indicadores!D27:D554),"MM")&"/"&TEXT(XLOOKUP(H20,Indicadores!N27:N554,Indicadores!D27:D554),"yyyy")&")"} -> (A partir de 01/2024)
B20: Faturamento Total | E20: {=IF($C$8>=$C$7,AVERAGE(XLOOKUP($C$7,Indicadores!$D$27:$D554,Indicadores!P$27:P554):XLOOKUP($C$8,Indicadores!$D$27:$D554,Indicadores!P$27:P554)),"Insira uma Data Final maior ou igual à Data Inicial")} -> 0 | F20: {=IF($C$8>=$C$7,AVERAGE(XLOOKUP($C$7,Indicadores!$D$27:$D554,Indicadores!I$27:I554):XLOOKUP($C$8,Indicadores!$D$27:$D554,Indicadores!I$27:I554)),"Insira uma Data Final maior ou igual à Data Inicial")} -> #N/A | G20: {=IF($C$8>=$C$7,SUM(XLOOKUP($C$7,Indicadores!$D$27:$D554,Indicadores!G$27:G554):XLOOKUP($C$8,Indicadores!$D$27:$D554,Indicadores!G$27:G554)),"Insira uma Data Final maior ou igual à Data Inicial")} -> #N/A | H20: {=IF($C$8>=$C$7,MAX(XLOOKUP($C$7,Indicadores!$D$27:$D554,Indicadores!N$27:N554):XLOOKUP($C$8,Indicadores!$D$27:$D554,Indicadores!N$27:N554)),"Insira uma Data Final maior ou igual à Data Inicial")} -> 0 | I20: {=IF($C$8>=$C$7,SUM(XLOOKUP($C$7,Indicadores!$D$27:$D554,Indicadores!G$27:G554):XLOOKUP($C$8,Indicadores!$D$27:$D554,Indicadores!G$27:G554))/SUM(XLOOKUP(C7,Indicadores!$D$27:$D554,Indicadores!$E$27:$E554):XLOOKUP(C8,Indicadores!$D$27:$D554,Indicadores!$E$27:$E554)),"Insira uma Data Final maior ou igual à Data Inicial")} -> #N/A
B22: {=IF(C8>=C7,SUM(XLOOKUP(C7,Indicadores!$D$27:$D554,Indicadores!$R$27:$R554):XLOOKUP(C8,Indicadores!$D$27:$D554,Indicadores!$R$27:$R554)),"Insira uma Data Final maior ou igual à Data Inicial")} -> #N/A
C27: Total
B28: =IFERROR(__xludf.DUMMYFUNCTION("Filter(teste!W8:W554,teste!T8:T554=""Entrada"")"),"Ensaio de Casal") -> Ensaio de Casal | C28: =SUM(AD8:AD554) -> #REF! | D28: =C28/$B$12 -> #REF!
B29: =IFERROR(__xludf.DUMMYFUNCTION("""COMPUTED_VALUE"""),"Ensaio simples") -> Ensaio simples | C29: =SUM(AE8:AE554) -> #REF! | D29: =C29/$B$12 -> #REF!
B30: =IFERROR(__xludf.DUMMYFUNCTION("""COMPUTED_VALUE"""),"Ensaio de 15 anos") -> Ensaio de 15 anos | C30: =SUM(AF8:AF554) -> #REF! | D30: =C30/$B$12 -> #REF!
B31: =IFERROR(__xludf.DUMMYFUNCTION("""COMPUTED_VALUE"""),"Ensaio de Formatura") -> Ensaio de Formatura | C31: =SUM(AG8:AG554) -> #REF! | D31: =C31/$B$12 -> #REF!
B32: =IFERROR(__xludf.DUMMYFUNCTION("""COMPUTED_VALUE"""),"Ensaio de Noivos") -> Ensaio de Noivos | C32: =SUM(AH8:AH554) -> #REF! | D32: =C32/$B$12 -> #REF!

Sheet teste
B1: Plano de Contas
A7: Fluxo | B7: Tipo de Custo | C7: Centro de Custo | D7: Nome | E7: Filtro p/ deletar CC inteiro | G7: =COUNTIFS(G8:G1022,"<>") -> 0 | H7: Filtro p/ deletar itens do TC inteiro | J7: =COUNTIFS(J8:J1022,"<>") -> 0 | K7: Filtro deletar CCs do TC e o próprio TC | L7: =COUNTIFS(L8:L1022,"<>") -> 0 | P7: Tipo de Custo | Q7: Centro de Custo | R7: Nome | T7: Fluxo | U7: Tipo de Custo | V7: Centro de Custo | W7: Nome
A8: Entrada | B8: Receitas | E8: =IFERROR(__xludf.DUMMYFUNCTION("IFERROR(FILTER(B7:D1022,C7:C1022='Gastos Fixos'!H10,D7:D1022<>""""),)"),"") | H8: =IFERROR(__xludf.DUMMYFUNCTION("IFERROR(FILTER(B7:D1022,B7:B1022='Gastos Fixos'!D10,C7:C1022<>"""",D7:D1022<>""""),)"),"") | K8: =IFERROR(__xludf.DUMMYFUNCTION("IFERROR(FILTER(B7:C1022,B7:B1022='Gastos Fixos'!D10,C7:C1022<>""""),)"),"") | P8: =IFERROR(__xludf.DUMMYFUNCTION("IFERROR(FILTER(B7:B1022,'Gastos Fixos'!C10=A7:A1022),)"),"") | Q8: =IFERROR(__xludf.DUMMYFUNCTION("IFERROR(FILTER(C7:C1022,'Gastos Fixos'!D10=B7:B1022,'Gastos Fixos'!C10=A7:A1022),)"),"") | R8: =IFERROR(__xludf.DUMMYFUNCTION("IFERROR(FILTER(D7:D1022,'Gastos Fixos'!H10=C7:C1022,'Gastos Fixos'!D10=B7:B1022,'Gastos Fixos'!C10=A7:A1022),)"),"") | T8: =IFERROR(__xludf.DUMMYFUNCTION("QUERY(A8:D1022,""select A,B,C,D where D is not null"")"),"Entrada") -> Entrada | U8: =IFERROR(__xludf.DUMMYFUNCTION("""COMPUTED_VALUE"""),"Receitas") -> Receitas | V8: =IFERROR(__xludf.DUMMYFUNCTION("""COMPUTED_VALUE"""),"Faturamento Baixo") -> Faturamento Baixo | W8: =IFERROR(__xludf.DUMMYFUNCTION("""COMPUTED_VALUE"""),"Ensaio de Casal") -> Ensaio de Casal
A9: Saída | B9: Investimentos | T9: =IFERROR(__xludf.DUMMYFUNCTION("""COMPUTED_VALUE"""),"Entrada") -> Entrada | U9: =IFERROR(__xludf.DUMMYFUNCTION("""COMPUTED_VALUE"""),"Receitas") -> Receitas | V9: =IFERROR(__xludf.DUMMYFUNCTION("""COMPUTED_VALUE"""),"Faturamento Baixo") -> Faturamento Baixo | W9: =IFERROR(__xludf.DUMMYFUNCTION("""COMPUTED_VALUE"""),"Ensaio simples") -> Ensaio simples
A10: Saída | B10: Custos Variáveis | T10: =IFERROR(__xludf.DUMMYFUNCTION("""COMPUTED_VALUE"""),"Entrada") -> Entrada | U10: =IFERROR(__xludf.DUMMYFUNCTION("""COMPUTED_VALUE"""),"Receitas") -> Receitas | V10: =IFERROR(__xludf.DUMMYFUNCTION("""COMPUTED_VALUE"""),"Faturamento Baixo") -> Faturamento Baixo | W10: =IFERROR(__xludf.DUMMYFUNCTION("""COMPUTED_VALUE"""),"Ensaio de 15 anos") -> Ensaio de 15 anos
A11: Saída | B11: Despesas | T11: =IFERROR(__xludf.DUMMYFUNCTION("""COMPUTED_VALUE"""),"Entrada") -> Entrada | U11: =IFERROR(__xludf.DUMMYFUNCTION("""COMPUTED_VALUE"""),"Receitas") -> Receitas | V11: =IFERROR(__xludf.DUMMYFUNCTION("""COMPUTED_VALUE"""),"Faturamento Alto") -> Faturamento Alto | W11: =IFERROR(__xludf.DUMMYFUNCTION("""COMPUTED_VALUE"""),"Ensaio de Formatura") -> Ensaio de Formatura
A12: Saída | B12: Custos Fixos | T12: =IFERROR(__xludf.DUMMYFUNCTION("""COMPUTED_VALUE"""),"Entrada") -> Entrada | U12: =IFERROR(__xludf.DUMMYFUNCTION("""COMPUTED_VALUE"""),"Receitas") -> Receitas | V12: =IFERROR(__xludf.DUMMYFUNCTION("""COMPUTED_VALUE"""),"Faturamento Alto") -> Faturamento Alto | W12: =IFERROR(__xludf.DUMMYFUNCTION("""COMPUTED_VALUE"""),"Ensaio de Noivos") -> Ensaio de Noivos
A13: Entrada | B13: Receitas | C13: Faturamento Baixo | T13: =IFERROR(__xludf.DUMMYFUNCTION("""COMPUTED_VALUE"""),"Saída") -> Saída | U13: =IFERROR(__xludf.DUMMYFUNCTION("""COMPUTED_VALUE"""),"Custos Fixos") -> Custos Fixos | V13: =IFERROR(__xludf.DUMMYFUNCTION("""COMPUTED_VALUE"""),"Infraestrutura") -> Infraestrutura | W13: =IFERROR(__xludf.DUMMYFUNCTION("""COMPUTED_VALUE"""),"Aluguel de Equipamentos") -> Aluguel de Equipamentos
A14: Entrada | B14: Receitas | C14: Faturamento Baixo | D14: Ensaio de Casal | T14: =IFERROR(__xludf.DUMMYFUNCTION("""COMPUTED_VALUE"""),"Saída") -> Saída | U14: =IFERROR(__xludf.DUMMYFUNCTION("""COMPUTED_VALUE"""),"Custos Fixos") -> Custos Fixos | V14: =IFERROR(__xludf.DUMMYFUNCTION("""COMPUTED_VALUE"""),"Infraestrutura") -> Infraestrutura | W14: =IFERROR(__xludf.DUMMYFUNCTION("""COMPUTED_VALUE"""),"Aluguel do Estúdio") -> Aluguel do Estúdio
A15: Entrada | B15: Receitas | C15: Faturamento Baixo | D15: Ensaio simples | T15: =IFERROR(__xludf.DUMMYFUNCTION("""COMPUTED_VALUE"""),"Saída") -> Saída | U15: =IFERROR(__xludf.DUMMYFUNCTION("""COMPUTED_VALUE"""),"Custos Fixos") -> Custos Fixos | V15: =IFERROR(__xludf.DUMMYFUNCTION("""COMPUTED_VALUE"""),"Infraestrutura") -> Infraestrutura | W15: =IFERROR(__xludf.DUMMYFUNCTION("""COMPUTED_VALUE"""),"CEB") -> CEB
A16: Entrada | B16: Receitas | C16: Faturamento Baixo | D16: Ensaio de 15 anos | T16: =IFERROR(__xludf.DUMMYFUNCTION("""COMPUTED_VALUE"""),"Saída") -> Saída | U16: =IFERROR(__xludf.DUMMYFUNCTION("""COMPUTED_VALUE"""),"Custos Fixos") -> Custos Fixos | V16: =IFERROR(__xludf.DUMMYFUNCTION("""COMPUTED_VALUE"""),"Pessoal") -> Pessoal | W16: =IFERROR(__xludf.DUMMYFUNCTION("""COMPUTED_VALUE"""),"Salário - Fotógrafos") -> Salário - Fotógrafos
A17: Entrada | B17: Receitas | C17: Faturamento Alto | T17: =IFERROR(__xludf.DUMMYFUNCTION("""COMPUTED_VALUE"""),"Saída") -> Saída | U17: =IFERROR(__xludf.DUMMYFUNCTION("""COMPUTED_VALUE"""),"Custos Fixos") -> Custos Fixos | V17: =IFERROR(__xludf.DUMMYFUNCTION("""COMPUTED_VALUE"""),"Pessoal") -> Pessoal | W17: =IFERROR(__xludf.DUMMYFUNCTION("""COMPUTED_VALUE"""),"Salário - Atendente") -> Salário - Atendente
A18: Entrada | B18: Receitas | C18: Faturamento Alto | D18: Ensaio de Formatura | T18: =IFERROR(__xludf.DUMMYFUNCTION("""COMPUTED_VALUE"""),"Saída") -> Saída | U18: =IFERROR(__xludf.DUMMYFUNCTION("""COMPUTED_VALUE"""),"Custos Fixos") -> Custos Fixos | V18: =IFERROR(__xludf.DUMMYFUNCTION("""COMPUTED_VALUE"""),"Pessoal") -> Pessoal | W18: =IFERROR(__xludf.DUMMYFUNCTION("""COMPUTED_VALUE"""),"Vale Transporte") -> Vale Transporte
A19: Entrada | B19: Receitas | C19: Faturamento Alto | D19: Ensaio de Noivos | T19: =IFERROR(__xludf.DUMMYFUNCTION("""COMPUTED_VALUE"""),"Saída") -> Saída | U19: =IFERROR(__xludf.DUMMYFUNCTION("""COMPUTED_VALUE"""),"Custos Fixos") -> Custos Fixos | V19: =IFERROR(__xludf.DUMMYFUNCTION("""COMPUTED_VALUE"""),"Pessoal") -> Pessoal | W19: =IFERROR(__xludf.DUMMYFUNCTION("""COMPUTED_VALUE"""),"Vale Alimentação") -> Vale Alimentação
A20: Saída | B20: Custos Fixos | C20: Infraestrutura | T20: =IFERROR(__xludf.DUMMYFUNCTION("""COMPUTED_VALUE"""),"Saída") -> Saída | U20: =IFERROR(__xludf.DUMMYFUNCTION("""COMPUTED_VALUE"""),"Custos Variáveis") -> Custos Variáveis | V20: =IFERROR(__xludf.DUMMYFUNCTION("""COMPUTED_VALUE"""),"Encargos Governo") -> Encargos Governo | W20: =IFERROR(__xludf.DUMMYFUNCTION("""COMPUTED_VALUE"""),"Impostos") -> Impostos
A21: Saída | B21: Custos Fixos | C21: Infraestrutura | D21: Aluguel de Equipamentos | T21: =IFERROR(__xludf.DUMMYFUNCTION("""COMPUTED_VALUE"""),"Saída") -> Saída | U21: =IFERROR(__xludf.DUMMYFUNCTION("""COMPUTED_VALUE"""),"Custos Variáveis") -> Custos Variáveis | V21: =IFERROR(__xludf.DUMMYFUNCTION("""COMPUTED_VALUE"""),"Encargos Sociais") -> Encargos Sociais | W21: =IFERROR(__xludf.DUMMYFUNCTION("""COMPUTED_VALUE"""),"13° Salário") -> 13° Salário
A22: Saída | B22: Custos Fixos | C22: Infraestrutura | D22: Aluguel do Estúdio | T22: =IFERROR(__xludf.DUMMYFUNCTION("""COMPUTED_VALUE"""),"Saída") -> Saída | U22: =IFERROR(__xludf.DUMMYFUNCTION("""COMPUTED_VALUE"""),"Despesas") -> Despesas | V22: =IFERROR(__xludf.DUMMYFUNCTION("""COMPUTED_VALUE"""),"Operacional") -> Operacional | W22: =IFERROR(__xludf.DUMMYFUNCTION("""COMPUTED_VALUE"""),"Internet") -> Internet
A23: Saída | B23: Custos Fixos | C23: Infraestrutura | D23: CEB | T23: =IFERROR(__xludf.DUMMYFUNCTION("""COMPUTED_VALUE"""),"Saída") -> Saída | U23: =IFERROR(__xludf.DUMMYFUNCTION("""COMPUTED_VALUE"""),"Despesas") -> Despesas | V23: =IFERROR(__xludf.DUMMYFUNCTION("""COMPUTED_VALUE"""),"Operacional") -> Operacional | W23: =IFERROR(__xludf.DUMMYFUNCTION("""COMPUTED_VALUE"""),"Telefone") -> Telefone
A24: Saída | B24: Custos Fixos | C24: Pessoal | T24: =IFERROR(__xludf.DUMMYFUNCTION("""COMPUTED_VALUE"""),"Saída") -> Saída | U24: =IFERROR(__xludf.DUMMYFUNCTION("""COMPUTED_VALUE"""),"Despesas") -> Despesas | V24: =IFERROR(__xludf.DUMMYFUNCTION("""COMPUTED_VALUE"""),"Operacional") -> Operacional | W24: =IFERROR(__xludf.DUMMYFUNCTION("""COMPUTED_VALUE"""),"Software") -> Software
A25: Saída | B25: Custos Fixos | C25: Pessoal | D25: Salário - Fotógrafos | T25: =IFERROR(__xludf.DUMMYFUNCTION("""COMPUTED_VALUE"""),"Saída") -> Saída | U25: =IFERROR(__xludf.DUMMYFUNCTION("""COMPUTED_VALUE"""),"Despesas") -> Despesas | V25: =IFERROR(__xludf.DUMMYFUNCTION("""COMPUTED_VALUE"""),"Operacional") -> Operacional | W25: =IFERROR(__xludf.DUMMYFUNCTION("""COMPUTED_VALUE"""),"CAESB") -> CAESB
A26: Saída | B26: Custos Fixos | C26: Pessoal | D26: Salário - Atendente | T26: =IFERROR(__xludf.DUMMYFUNCTION("""COMPUTED_VALUE"""),"Saída") -> Saída | U26: =IFERROR(__xludf.DUMMYFUNCTION("""COMPUTED_VALUE"""),"Despesas") -> Despesas | V26: =IFERROR(__xludf.DUMMYFUNCTION("""COMPUTED_VALUE"""),"Terceirizados") -> Terceirizados | W26: =IFERROR(__xludf.DUMMYFUNCTION("""COMPUTED_VALUE"""),"Contador") -> Contador
A27: Saída | B27: Custos Fixos | C27: Pessoal | D27: Vale Transporte | T27: =IFERROR(__xludf.DUMMYFUNCTION("""COMPUTED_VALUE"""),"Saída") -> Saída | U27: =IFERROR(__xludf.DUMMYFUNCTION("""COMPUTED_VALUE"""),"Despesas") -> Despesas | V27: =IFERROR(__xludf.DUMMYFUNCTION("""COMPUTED_VALUE"""),"Terceirizados") -> Terceirizados | W27: =IFERROR(__xludf.DUMMYFUNCTION("""COMPUTED_VALUE"""),"Marketing") -> Marketing
A28: Saída | B28: Custos Fixos | C28: Pessoal | D28: Vale Alimentação
A29: Saída | B29: Custos Variáveis | C29: Encargos Governo
A30: Saída | B30: Custos Variáveis | C30: Encargos Governo | D30: Impostos
A31: Saída | B31: Custos Variáveis | C31: Encargos Sociais
A32: Saída | B32: Custos Variáveis | C32: Encargos Sociais | D32: 13° Salário
A33: Saída | B33: Despesas | C33: Operacional
A34: Saída | B34: Despesas | C34: Operacional | D34: Internet
A35: Saída | B35: Despesas | C35: Operacional | D35: Telefone
A36: Saída | B36: Despesas | C36: Operacional | D36: Software
A37: Saída | B37: Despesas | C37: Operacional | D37: CAESB
A38: Saída | B38: Despesas | C38: Terceirizados
A39: Saída | B39: Despesas | C39: Terceirizados | D39: Contador
A40: Saída | B40: Despesas | C40: Terceirizados | D40: Marketing

Sheet Registro
B1: Registro
A6: 0 | C6: SEERRO(FILTER( 'Base de Dados'!A7:Q; ('Base de Dados'!A7:A = C16) + (C16 = ""); ('Base de Dados'!E7:E = C17) + (C17 = ""); ('Base de Dados'!C7:C = C18) + (C18 = ""); ('Base de Dados'!I7:I = C19) + (C19 = ""); ('Base de Dados'!D7:D = C20) + (C20 = ""));) | D6: FILTER(A10:L14; (D10:D14 <> "") * (E10:E14 <> "") * (F10:F14 <> "") * (G10:G14 <> "") * (I10:I14 <> "") * (J10:J14 <> ""))
B8: Registrar | AD8: =COUNTA($U$11:$U$15) -> 1
B9: ID | C9: Data | D9: Item | E9: Fluxo | F9: Tipo | G9: Centro | H9: Descrição | I9: Forma de pagamento | J9: Valor Total | K9: Parcelas | L9: Desconto | V9: ID | W9: Data | X9: Item | Y9: Fluxo | Z9: Tipo | AA9: Centro | AB9: Descrição | AC9: Forma de pagamento | AD9: Valor Total | AE9: Parcelas | AF9: Desconto
A10: 1 | C10: 45986 | D10: CAESB | E10: {=IFERROR(XLOOKUP(D10,teste!$W$8:$W2003,teste!$T$8:$T2003),)} -> Saída | F10: {=IFERROR(XLOOKUP(D10,teste!$W$8:$W2003,teste!$U$8:$U2003),)} -> Despesas | G10: {=IFERROR(XLOOKUP(D10,teste!$W$8:$W2003,teste!$V$8:$V2003),)} -> Operacional | I10: Parcelamento | J10: 2000 | K10: 10 | U10: =U11 -> 1 | V10: =V11 | W10: =W11 -> 45986 | X10: =X11 -> CAESB | Y10: =Y11 -> Saída | Z10: =Z11 -> Despesas | AA10: =AA11 -> Operacional | AB10: =AB11 | ... AF10: =AF11
A11: 2 | E11: {=IFERROR(XLOOKUP(D11,teste!$W$8:$W2003,teste!$T$8:$T2003),)} | F11: {=IFERROR(XLOOKUP(D11,teste!$W$8:$W2003,teste!$U$8:$U2003),)} | G11: {=IFERROR(XLOOKUP(D11,teste!$W$8:$W2003,teste!$V$8:$V2003),)} | U11: =IFERROR(__xludf.DUMMYFUNCTION("FILTER(A10:L14, (D10:D14 <> """") * (E10:E14 <> """") * (F10:F14 <> """") * (G10:G14 <> """"))"),1.0) -> 1 | W11: =IFERROR(__xludf.DUMMYFUNCTION("""COMPUTED_VALUE"""),45986.0) -> 45986 | X11: =IFERROR(__xludf.DUMMYFUNCTION("""COMPUTED_VALUE"""),"CAESB") -> CAESB | Y11: =IFERROR(__xludf.DUMMYFUNCTION("""COMPUTED_VALUE"""),"Saída") -> Saída | Z11: =IFERROR(__xludf.DUMMYFUNCTION("""COMPUTED_VALUE"""),"Despesas") -> Despesas | AA11: =IFERROR(__xludf.DUMMYFUNCTION("""COMPUTED_VALUE"""),"Operacional") -> Operacional | AC11: =IFERROR(__xludf.DUMMYFUNCTION("""COMPUTED_VALUE"""),"Parcelamento") -> Parcelamento | AD11: =IFERROR(__xludf.DUMMYFUNCTION("""COMPUTED_VALUE"""),2000.0) -> 2000 | AE11: =IFERROR(__xludf.DUMMYFUNCTION("""COMPUTED_VALUE"""),10.0) -> 10
A12: 3 | E12: {=IFERROR(XLOOKUP(D12,teste!$W$8:$W2003,teste!$T$8:$T2003),)} | F12: {=IFERROR(XLOOKUP(D12,teste!$W$8:$W2003,teste!$U$8:$U2003),)} | G12: {=IFERROR(XLOOKUP(D12,teste!$W$8:$W2003,teste!$V$8:$V2003),)}
A13: 4 | E13: {=IFERROR(XLOOKUP(D13,teste!$W$8:$W2003,teste!$T$8:$T2003),)} | F13: {=IFERROR(XLOOKUP(D13,teste!$W$8:$W2003,teste!$U$8:$U2003),)} | G13: {=IFERROR(XLOOKUP(D13,teste!$W$8:$W2003,teste!$V$8:$V2003),)}
A14: 5 | E14: {=IFERROR(XLOOKUP(D14,teste!$W$8:$W2003,teste!$T$8:$T2003),)} | F14: {=IFERROR(XLOOKUP(D14,teste!$W$8:$W2003,teste!$U$8:$U2003),)} | G14: {=IFERROR(XLOOKUP(D14,teste!$W$8:$W2003,teste!$V$8:$V2003),)}
A15: Proteger intervalo acima (A10:A14) e esconder seus números | E15: Proteger intervalo acima (E10:G14)
C18: Pesquisar | E18: Sim
C19: ID | D19: Forma de Pagamento | E19: Item
D20: À vista
C24: ID | D24: Data | E24: Confirmação de Pagamento | F24: Item | G24: Fluxo | H24: Tipo | I24: Centro | J24: Descrição | K24: Forma de pagamento | L24: Parcela | M24: Valor Total | N24: Desconto | O24: Valor final | P24: Dia | Q24: Mês | R24: Ano | S24: N°
C25: =IFERROR(__xludf.DUMMYFUNCTION("IFERROR(IF($E$18=""Sim"", FILTER( 'Base de Dados'!$A$7:$Q2003, ARRAYFORMULA(SEARCH($E$20,'Base de Dados'!$D$7:$D2003)) + ($E$20 = """"), ARRAYFORMULA(SEARCH($D$20,'Base de Dados'!$I$7:$I2003)) + ($D$20 = """"),ARRAYFORMULA(SEARCH($C$20,'Base de Dados'!$A$"&"7:$A2003)) + ($C$20 = """"),$A$6<>'Base de Dados'!$Q$7:$Q2003,$A$6<>'Base de Dados'!$A$7:$A2003),))"),"")

Sheet Registro de Fichas Técnicas
B1: Registro de Fichas Técnicas
B8: Registro de Fichas Técnicas
B10: Nome | D10: Custo Total
B11: Ficha Técnica 1 | D11: =SUM(F15:F35) -> 0
B14: Recurso Utilizado | C14: Quantidade | D14: Unidade de Medida | E14: Observações | F14: Custo Unitario
F15: {=XLOOKUP($B15,'Registro de Insumos'!$D:$D,'Registro de Insumos'!$H:$H,) * $C15} -> 0
F16: {=XLOOKUP($B16,'Registro de Insumos'!$D:$D,'Registro de Insumos'!$H:$H,) * $C16} -> 0
F17: {=XLOOKUP($B17,'Registro de Insumos'!$D:$D,'Registro de Insumos'!$H:$H,) * $C17} -> 0
F18: {=XLOOKUP($B18,'Registro de Insumos'!$D:$D,'Registro de Insumos'!$H:$H,) * $C18} -> 0
F19: {=XLOOKUP($B19,'Registro de Insumos'!$D:$D,'Registro de Insumos'!$H:$H,) * $C19} -> 0
F20: {=XLOOKUP($B20,'Registro de Insumos'!$D:$D,'Registro de Insumos'!$H:$H,) * $C20} -> 0
F21: {=XLOOKUP($B21,'Registro de Insumos'!$D:$D,'Registro de Insumos'!$H:$H,) * $C21} -> 0
F22: {=XLOOKUP($B22,'Registro de Insumos'!$D:$D,'Registro de Insumos'!$H:$H,) * $C22} -> 0
F23: {=XLOOKUP($B23,'Registro de Insumos'!$D:$D,'Registro de Insumos'!$H:$H,) * $C23} -> 0
F24: {=XLOOKUP($B24,'Registro de Insumos'!$D:$D,'Registro de Insumos'!$H:$H,) * $C24} -> 0
F25: {=XLOOKUP($B25,'Registro de Insumos'!$D:$D,'Registro de Insumos'!$H:$H,) * $C25} -> 0
F26: {=XLOOKUP($B26,'Registro de Insumos'!$D:$D,'Registro de Insumos'!$H:$H,) * $C26} -> 0
... F35: {=XLOOKUP($B35,'Registro de Insumos'!$D:$D,'Registro de Insumos'!$H:$H,) * $C35} -> 0
B39: ID Ficha-Técnica | C39: Nome | D39: Recurso Utilizado | E39: Quantidade | F39: Unidade de Medida | G39: Observações | H39: Custo Unitario

Sheet Base de Salários
B1: Base de Salários
A6: 0 | C6: SEERRO(FILTER( 'Base de Dados'!A7:Q; ('Base de Dados'!A7:A = C16) + (C16 = ""); ('Base de Dados'!E7:E = C17) + (C17 = ""); ('Base de Dados'!C7:C = C18) + (C18 = ""); ('Base de Dados'!I7:I = C19) + (C19 = ""); ('Base de Dados'!D7:D = C20) + (C20 = ""));) | D6: FILTER(A10:L14; (D10:D14 <> "") * (E10:E14 <> "") * (F10:F14 <> "") * (G10:G14 <> "") * (I10:I14 <> "") * (J10:J14 <> ""))
B8: Editar | C8: Registro | AD8: =COUNTA($U$11:$U$15) -> 1
B9: Registro | C9: Cargo | D9: Área | E9: Quantidade | F9: Remuneração | G9: Horas trabalhadas p/ mês | U9: ID | V9: Data | W9: Item | X9: Fluxo | Y9: Tipo | Z9: Centro | AA9: Descrição | AB9: Forma de pagamento | AC9: Valor Total | AD9: Parcelas | AE9: Desconto
U10: =U11 -> #N/A | V10: =V11 | W10: =W11 | X10: =X11 | Y10: =Y11 | Z10: =Z11 | AA10: =AA11 | AB10: =AB11 | ... AF10: =AF11
U11: =IFERROR(__xludf.DUMMYFUNCTION("FILTER(A10:L14, (D10:D14 <> """") * (E10:E14 <> """") * (F10:F14 <> """") * (G10:G14 <> """"))"),"#N/A") -> #N/A
I12: Faturamento Estimado | J12: ='Gastos Fixos'!H9 -> 10100428
I13: Soma das Despesas | J13: =SUM(G18:G996) -> 85281.93
I14: % Salários vs Faturamento | J14: =J13/J12 -> 0.0084433977
C17: ID | D17: Profissional | E17: Área | F17: Quantidade | G17: Remuneração | H17: Horas trabalhadas p/ mês | I17: Salário [Hora] | J17: Salário [Dia]
C18: 1 | D18: Ajudante Geral - Ricardo | E18: Montagem | F18: 1 | G18: 3094.2 | H18: 220 | I18: 14.064545 | J18: 112.51636
C19: 2 | D19: Ajudante Geral - Tierry | E19: Montagem | F19: 1 | G19: 3094.2 | H19: 220 | I19: 14.064545 | J19: 112.51636
C20: 3 | D20: Almoxarifado | E20: Almoxarifado | F20: 1 | G20: 3687.8 | H20: 220 | I20: 16.762727 | J20: 134.10182
C21: 4 | D21: Analista de RH | E21: Engenharia | F21: 1 | G21: 5459 | H21: 220 | I21: 24.813636 | J21: 198.50909
C22: 5 | D22: Assistente Administrativo | E22: Engenharia | F22: 1 | G22: 3935.47 | H22: 220 | I22: 17.8885 | J22: 143.108
C23: 6 | D23: Auxiliar de Eletricista - Alisson | E23: Montagem | F23: 1 | G23: 3602.8 | H23: 220 | I23: 16.376364 | J23: 131.01091
C24: 7 | D24: Auxiliar de Eletricista - Bruno | E24: Montagem | F24: 1 | G24: 3547.8 | H24: 220 | I24: 16.126364 | J24: 129.01091
C25: 8 | D25: Auxiliar de Eletricista - Manoel | E25: Montagem | F25: 1 | G25: 3602.8 | H25: 220 | I25: 16.376364 | J25: 131.01091
C26: 9 | D26: Auxiliar de Limpeza | E26: Limpeza | F26: 1 | G26: 3094.2 | H26: 220 | I26: 14.064545 | J26: 112.51636
C27: 10 | D27: Eletricista - Antonio | E27: Montagem | F27: 1 | G27: 4498.8 | H27: 220 | I27: 20.449091 | J27: 163.59273
C28: 11 | D28: Eletricista - Joeilson | E28: Montagem | F28: 1 | G28: 4864.32 | H28: 220 | I28: 22.110545 | J28: 176.88436
C29: 12 | D29: Eletricista - Wandercy | E29: Montagem | F29: 1 | G29: 4406.4 | H29: 220 | I29: 20.029091 | J29: 160.23273
... C36: 19 | D36: Serralheiro | E36: Serralheria | F36: 1 | G36: 4392.92 | H36: 220 | I36: 19.967818 | J36: 159.74255

Sheet Config_Unidades
A1: Unidade
A2: gramas
A3: kg
A4: litros
A5: mg
A6: caixa
A7: pacote
A8: Cristiano Rose

Sheet Precificação Produto | Custo Co
B1: Preço de Venda de Produto com Custo Conhecido
E6: FILTER(A10:L14; (D10:D14 <> "") * (E10:E14 <> "") * (F10:F14 <> "") * (G10:G14 <> "") * (I10:I14 <> "") * (J10:J14 <> ""))
C7: Seleção de ficha | J7: Informações Extras | M7: DRE do Projeto | O7: Individual | R7: Lote
B9: Editar | C9: Código do Produto | D9: Nome do Item | E9: Quantidade | F9: Quantidade Referência | G9: Valor Referência | H9: Valor Custo | J9: Margem de Lucro | K9: Porcentagem | M9: DRE - Projeto | O9: Valor | P9: % do Preço | R9: Valor | S9: % do Preço
J10: Margem Desejada | K10: 0.1 | M10: Preço de Venda | O10: =K27 -> 0 | P10: =K14*K25/O10 -> #DIV/0! | R10: 0.3 | S10: 0.3
J12: Unidades desse Lote | K12: Quantidade Unitária | M12: =#REF! -> #REF! | O12: =IFERROR(P12*$O$10,"") -> 0 | P12: =IFERROR(VLOOKUP(M12,'Gastos Variáveis'!D:E,2,FALSE),"") | R12: =#REF! -> #REF! | S12: =#REF! -> #REF!
J13: Quantidade produzida | K13: 10 | M13: =#REF! -> #REF! | O13: =IFERROR(P13*$O$10,"") -> 0 | P13: =IFERROR(VLOOKUP(M13,'Gastos Variáveis'!D:E,2,FALSE),"") | R13: =#REF! -> #REF! | S13: =#REF! -> #REF!
J14: Custo Direto Unitário | K14: =(SUM(H10:H9999))/K13 -> 0 | M14: =#REF! -> #REF! | O14: =IFERROR(P14*$O$10,"") -> 0 | P14: =IFERROR(VLOOKUP(M14,'Gastos Variáveis'!D:E,2,FALSE),"") | R14: =#REF! -> #REF! | S14: =#REF! -> #REF!
F15: =IFERROR(VLOOKUP(D15,'Registro de Insumos'!D:G,3,FALSE),"") | G15: =IFERROR(VLOOKUP(D15,'Registro de Insumos'!D:G,4,FALSE),"") | H15: =IFERROR((G15/F15)*E15,"") | M15: ='Gastos Variáveis'!D14 -> Impostos | O15: =IFERROR(P15*$O$10,"") -> 0 | P15: =IFERROR(VLOOKUP(M15,'Gastos Variáveis'!D:E,2,FALSE),"") -> 0.0094 | R15: ='Gastos Variáveis'!I14 | S15: ='Gastos Variáveis'!J14
F16: =IFERROR(VLOOKUP(D16,'Registro de Insumos'!D:G,3,FALSE),"") | G16: =IFERROR(VLOOKUP(D16,'Registro de Insumos'!D:G,4,FALSE),"") | H16: =IFERROR((G16/F16)*E16,"") | O16: =IFERROR(P16*$O$10,"") -> 0 | P16: =IFERROR(VLOOKUP(M16,'Gastos Variáveis'!D:E,2,FALSE),"") | R16: ='Gastos Variáveis'!I15 | S16: ='Gastos Variáveis'!J15
F17: =IFERROR(VLOOKUP(D17,'Registro de Insumos'!D:G,3,FALSE),"") | G17: =IFERROR(VLOOKUP(D17,'Registro de Insumos'!D:G,4,FALSE),"") | H17: =IFERROR((G17/F17)*E17,"") | J17: Precificação do Produto | M17: ='Gastos Variáveis'!D16 | O17: =IFERROR(P17*$O$10,"") -> 0 | P17: =IFERROR(VLOOKUP(M17,'Gastos Variáveis'!D:E,2,FALSE),"") | R17: ='Gastos Variáveis'!I16 | S17: ='Gastos Variáveis'!J16
F18: =IFERROR(VLOOKUP(D18,'Registro de Insumos'!D:G,3,FALSE),"") | G18: =IFERROR(VLOOKUP(D18,'Registro de Insumos'!D:G,4,FALSE),"") | H18: =IFERROR((G18/F18)*E18,"") | I18: Horas trabalhadas p/ mês | M18: ='Gastos Variáveis'!D17 | O18: =IFERROR(P18*$O$10,"") -> 0 | P18: =IFERROR(VLOOKUP(M18,'Gastos Variáveis'!D:E,2,FALSE),"") | R18: ='Gastos Variáveis'!I17 | S18: ='Gastos Variáveis'!J17
F19: =IFERROR(VLOOKUP(D19,'Registro de Insumos'!D:G,3,FALSE),"") | G19: =IFERROR(VLOOKUP(D19,'Registro de Insumos'!D:G,4,FALSE),"") | H19: =IFERROR((G19/F19)*E19,"") | I19: 160 | J19: Informações | K19: Valor | M19: ='Gastos Variáveis'!D18 | O19: =IFERROR(P19*$O$10,"") -> 0 | P19: =IFERROR(VLOOKUP(M19,'Gastos Variáveis'!D:E,2,FALSE),"") | R19: ='Gastos Variáveis'!I18 | S19: ='Gastos Variáveis'!J18
F20: =IFERROR(VLOOKUP(D20,'Registro de Insumos'!D:G,3,FALSE),"") | G20: =IFERROR(VLOOKUP(D20,'Registro de Insumos'!D:G,4,FALSE),"") | H20: =IFERROR((G20/F20)*E20,"") | I20: 176 | J20: Custo Fixo | K20: ='Gastos Fixos'!H11 -> 0.20082555 | M20: Total Custos Variáveis | O20: 0.3 | P20: 0.3 | R20: 0.3 | S20: 0.3
F21: =IFERROR(VLOOKUP(D21,'Registro de Insumos'!D:G,3,FALSE),"") | G21: =IFERROR(VLOOKUP(D21,'Registro de Insumos'!D:G,4,FALSE),"") | H21: =IFERROR((G21/F21)*E21,"") | I21: 176 | J21: Custo Variável | K21: ='Gastos Variáveis'!H9 -> 0.0094 | M21: Total Custos Fixos | O21: 0.3 | P21: 0.3 | R21: 0.3 | S21: 0.3
F22: =IFERROR(VLOOKUP(D22,'Registro de Insumos'!D:G,3,FALSE),"") | G22: =IFERROR(VLOOKUP(D22,'Registro de Insumos'!D:G,4,FALSE),"") | H22: =IFERROR((G22/F22)*E22,"") | J22: Margem | K22: =K10 -> 0.1 | M22: Custo do Produto | O22: 0.3 | P22: 0.3 | R22: 0.3 | S22: 0.3
F23: =IFERROR(VLOOKUP(D23,'Registro de Insumos'!D:G,3,FALSE),"") | G23: =IFERROR(VLOOKUP(D23,'Registro de Insumos'!D:G,4,FALSE),"") | H23: =IFERROR((G23/F23)*E23,"") | J23: Salários | K23: ='Base de Salários'!J14 -> 0.0084433977 | M23: Total de Custos | O23: 0.3 | P23: 0.3 | R23: 0.3 | S23: 0.3
F24: =IFERROR(VLOOKUP(D24,'Registro de Insumos'!D:G,3,FALSE),"") | G24: =IFERROR(VLOOKUP(D24,'Registro de Insumos'!D:G,4,FALSE),"") | H24: =IFERROR((G24/F24)*E24,"") | J24: Soma | K24: =SUM(K20:K23) -> 0.31866895
F25: =IFERROR(VLOOKUP(D25,'Registro de Insumos'!D:G,3,FALSE),"") | G25: =IFERROR(VLOOKUP(D25,'Registro de Insumos'!D:G,4,FALSE),"") | H25: =IFERROR((G25/F25)*E25,"") | J25: Markup | K25: =1/(1-(K20+K21+K22+K23)) -> 1.4677153 | M25: Margem de Lucro | O25: 0.3 | P25: 0.3 | R25: 0.3 | S25: 0.3
F26: =IFERROR(VLOOKUP(D26,'Registro de Insumos'!D:G,3,FALSE),"") | G26: =IFERROR(VLOOKUP(D26,'Registro de Insumos'!D:G,4,FALSE),"") | H26: =IFERROR((G26/F26)*E26,"")
F27: =IFERROR(VLOOKUP(D27,'Registro de Insumos'!D:G,3,FALSE),"") | G27: =IFERROR(VLOOKUP(D27,'Registro de Insumos'!D:G,4,FALSE),"") | H27: =IFERROR((G27/F27)*E27,"") | J27: Preço de Venda | K27: =K14*K25 -> 0
F28: =IFERROR(VLOOKUP(D28,'Registro de Insumos'!D:G,3,FALSE),"") | G28: =IFERROR(VLOOKUP(D28,'Registro de Insumos'!D:G,4,FALSE),"") | H28: =IFERROR((G28/F28)*E28,"")
F29: =IFERROR(VLOOKUP(D29,'Registro de Insumos'!D:G,3,FALSE),"") | G29: =IFERROR(VLOOKUP(D29,'Registro de Insumos'!D:G,4,FALSE),"") | H29: =IFERROR((G29/F29)*E29,"")
F30: =IFERROR(VLOOKUP(D30,'Registro de Insumos'!D:G,3,FALSE),"") | G30: =IFERROR(VLOOKUP(D30,'Registro de Insumos'!D:G,4,FALSE),"") | H30: =IFERROR((G30/F30)*E30,"")
F31: =IFERROR(VLOOKUP(D31,'Registro de Insumos'!D:G,3,FALSE),"") | G31: =IFERROR(VLOOKUP(D31,'Registro de Insumos'!D:G,4,FALSE),"") | H31: =IFERROR((G31/F31)*E31,"")
F32: =IFERROR(VLOOKUP(D32,'Registro de Insumos'!D:G,3,FALSE),"") | G32: =IFERROR(VLOOKUP(D32,'Registro de Insumos'!D:G,4,FALSE),"") | H32: =IFERROR((G32/F32)*E32,"")
F33: =IFERROR(VLOOKUP(D33,'Registro de Insumos'!D:G,3,FALSE),"") | G33: =IFERROR(VLOOKUP(D33,'Registro de Insumos'!D:G,4,FALSE),"") | H33: =IFERROR((G33/F33)*E33,"")
F34: =IFERROR(VLOOKUP(D34,'Registro de Insumos'!D:G,3,FALSE),"") | G34: =IFERROR(VLOOKUP(D34,'Registro de Insumos'!D:G,4,FALSE),"") | H34: =IFERROR((G34/F34)*E34,"")
F35: =IFERROR(VLOOKUP(D35,'Registro de Insumos'!D:G,3,FALSE),"") | G35: =IFERROR(VLOOKUP(D35,'Registro de Insumos'!D:G,4,FALSE),"") | H35: =IFERROR((G35/F35)*E35,"")
F36: =IFERROR(VLOOKUP(D36,'Registro de Insumos'!D:G,3,FALSE),"") | G36: =IFERROR(VLOOKUP(D36,'Registro de Insumos'!D:G,4,FALSE),"") | H36: =IFERROR((G36/F36)*E36,"")
F37: =IFERROR(VLOOKUP(D37,'Registro de Insumos'!D:G,3,FALSE),"") | G37: =IFERROR(VLOOKUP(D37,'Registro de Insumos'!D:G,4,FALSE),"") | H37: =IFERROR((G37/F37)*E37,"")
F38: =IFERROR(VLOOKUP(D38,'Registro de Insumos'!D:G,3,FALSE),"") | G38: =IFERROR(VLOOKUP(D38,'Registro de Insumos'!D:G,4,FALSE),"") | H38: =IFERROR((G38/F38)*E38,"")
F39: =IFERROR(VLOOKUP(D39,'Registro de Insumos'!D:G,3,FALSE),"") | G39: =IFERROR(VLOOKUP(D39,'Registro de Insumos'!D:G,4,FALSE),"") | H39: =IFERROR((G39/F39)*E39,"")
... F101: =IFERROR(VLOOKUP(D101,'Registro de Insumos'!D:G,3,FALSE),"") | G101: =IFERROR(VLOOKUP(D101,'Registro de Insumos'!D:G,4,FALSE),"") | H101: =IFERROR((G101/F101)*E101,"")

Sheet Precificação Produto | Custo De
B1: Preço de Venda de Produto com Preço Desconhecido
A6: 0 | C6: SEERRO(FILTER( 'Base de Dados'!A7:Q; ('Base de Dados'!A7:A = C16) + (C16 = ""); ('Base de Dados'!E7:E = C17) + (C17 = ""); ('Base de Dados'!C7:C = C18) + (C18 = ""); ('Base de Dados'!I7:I = C19) + (C19 = ""); ('Base de Dados'!D7:D = C20) + (C20 = ""));) | D6: FILTER(A10:L14; (D10:D14 <> "") * (E10:E14 <> "") * (F10:F14 <> "") * (G10:G14 <> "") * (I10:I14 <> "") * (J10:J14 <> ""))
C7: Preenchimento de Insumos | I7: Informações Extras
B9: Editar | C9: Nome do Item | D9: Quantidade | E9: Quantidade Referência | F9: Valor Referência | G9: Valor Custo | I9: Margem de Lucro | J9: Porcentagem
B10: Registro | C10: BLOCO CONTATO AUXILIAR FRONTAL BFCA 3NA+1NF COM PARAFUSO UI MAX=660/690 VOLTS AZUL MINICONTATOR CWCA | D10: 20 | E10: =IFERROR(VLOOKUP(C10,'Registro de Insumos'!D:G,3,FALSE),"") -> 1 | F10: =IFERROR(VLOOKUP(C10,'Registro de Insumos'!D:G,4,FALSE),"") -> 24.59 | G10: =IFERROR((F10/E10)*D10,"") -> 491.8 | I10: Margem Desejada | J10: 0.4
C11: BLOCO CONTATO AUXILIAR FRONTAL BFCA 3NA+1NF COM PARAFUSO UI MAX=660/690 VOLTS AZUL MINICONTATOR CWCA | D11: 43 | E11: =IFERROR(VLOOKUP(C11,'Registro de Insumos'!D:G,3,FALSE),"") -> 1 | F11: =IFERROR(VLOOKUP(C11,'Registro de Insumos'!D:G,4,FALSE),"") -> 24.59 | G11: =IFERROR((F11/E11)*D11,"") -> 1057.37
C12: FCT-06-SU 07/26 | D12: 56 | E12: =IFERROR(VLOOKUP(C12,'Registro de Insumos'!D:G,3,FALSE),"") -> 1 | F12: =IFERROR(VLOOKUP(C12,'Registro de Insumos'!D:G,4,FALSE),"") -> 0 | G12: =IFERROR((F12/E12)*D12,"") -> 0 | I12: Unidades desse Lote | J12: Quantidade Unitária
C13: CH ALLEN 6MM SATA | D13: 13 | E13: =IFERROR(VLOOKUP(C13,'Registro de Insumos'!D:G,3,FALSE),"") -> 1 | F13: =IFERROR(VLOOKUP(C13,'Registro de Insumos'!D:G,4,FALSE),"") -> 6 | G13: =IFERROR((F13/E13)*D13,"") -> 78 | I13: Quantidade Produzida | J13: 1
E14: =IFERROR(VLOOKUP(C14,'Registro de Insumos'!D:G,3,FALSE),"") | F14: =IFERROR(VLOOKUP(C14,'Registro de Insumos'!D:G,4,FALSE),"") | G14: =IFERROR((F14/E14)*D14,"") | I14: Custo Unitário | J14: =(SUM(G10:G9999))/J13 -> 1627.17
E15: =IFERROR(VLOOKUP(C15,'Registro de Insumos'!D:G,3,FALSE),"") | F15: =IFERROR(VLOOKUP(C15,'Registro de Insumos'!D:G,4,FALSE),"") | G15: =IFERROR((F15/E15)*D15,"")
E16: =IFERROR(VLOOKUP(C16,'Registro de Insumos'!D:G,3,FALSE),"") | F16: =IFERROR(VLOOKUP(C16,'Registro de Insumos'!D:G,4,FALSE),"") | G16: =IFERROR((F16/E16)*D16,"")
E17: =IFERROR(VLOOKUP(C17,'Registro de Insumos'!D:G,3,FALSE),"") | F17: =IFERROR(VLOOKUP(C17,'Registro de Insumos'!D:G,4,FALSE),"") | G17: =IFERROR((F17/E17)*D17,"") | I17: Precificação do Produto
E18: =IFERROR(VLOOKUP(C18,'Registro de Insumos'!D:G,3,FALSE),"") | F18: =IFERROR(VLOOKUP(C18,'Registro de Insumos'!D:G,4,FALSE),"") | G18: =IFERROR((F18/E18)*D18,"") | H18: Horas trabalhadas p/ mês
E19: =IFERROR(VLOOKUP(C19,'Registro de Insumos'!D:G,3,FALSE),"") | F19: =IFERROR(VLOOKUP(C19,'Registro de Insumos'!D:G,4,FALSE),"") | G19: =IFERROR((F19/E19)*D19,"") | H19: 160 | I19: Informações | J19: Valor
E20: =IFERROR(VLOOKUP(C20,'Registro de Insumos'!D:G,3,FALSE),"") | F20: =IFERROR(VLOOKUP(C20,'Registro de Insumos'!D:G,4,FALSE),"") | G20: =IFERROR((F20/E20)*D20,"") | H20: 176 | I20: Custo Fixo | J20: ='Gastos Fixos'!H11 -> 0.20082555
E21: =IFERROR(VLOOKUP(C21,'Registro de Insumos'!D:G,3,FALSE),"") | F21: =IFERROR(VLOOKUP(C21,'Registro de Insumos'!D:G,4,FALSE),"") | G21: =IFERROR((F21/E21)*D21,"") | H21: 176 | I21: Custo Variável | J21: ='Gastos Variáveis'!H9 -> 0.0094
E22: =IFERROR(VLOOKUP(C22,'Registro de Insumos'!D:G,3,FALSE),"") | F22: =IFERROR(VLOOKUP(C22,'Registro de Insumos'!D:G,4,FALSE),"") | G22: =IFERROR((F22/E22)*D22,"") | I22: Margem | J22: =J10 -> 0.4
E23: =IFERROR(VLOOKUP(C23,'Registro de Insumos'!D:G,3,FALSE),"") | F23: =IFERROR(VLOOKUP(C23,'Registro de Insumos'!D:G,4,FALSE),"") | G23: =IFERROR((F23/E23)*D23,"") | I23: Salários | J23: ='Base de Salários'!J14 -> 0.0084433977
E24: =IFERROR(VLOOKUP(C24,'Registro de Insumos'!D:G,3,FALSE),"") | F24: =IFERROR(VLOOKUP(C24,'Registro de Insumos'!D:G,4,FALSE),"") | G24: =IFERROR((F24/E24)*D24,"") | I24: Soma | J24: =SUM(J20:J23) -> 0.61866895
E25: =IFERROR(VLOOKUP(C25,'Registro de Insumos'!D:G,3,FALSE),"") | F25: =IFERROR(VLOOKUP(C25,'Registro de Insumos'!D:G,4,FALSE),"") | G25: =IFERROR((F25/E25)*D25,"") | I25: Markup | J25: =1/(1-(J20+J21+J22+J23)) -> 2.6223933
E26: =IFERROR(VLOOKUP(C26,'Registro de Insumos'!D:G,3,FALSE),"") | F26: =IFERROR(VLOOKUP(C26,'Registro de Insumos'!D:G,4,FALSE),"") | G26: =IFERROR((F26/E26)*D26,"")
E27: =IFERROR(VLOOKUP(C27,'Registro de Insumos'!D:G,3,FALSE),"") | F27: =IFERROR(VLOOKUP(C27,'Registro de Insumos'!D:G,4,FALSE),"") | G27: =IFERROR((F27/E27)*D27,"") | I27: Preço de Venda | J27: =J14*J25 -> 4267.0798
E28: =IFERROR(VLOOKUP(C28,'Registro de Insumos'!D:G,3,FALSE),"") | F28: =IFERROR(VLOOKUP(C28,'Registro de Insumos'!D:G,4,FALSE),"") | G28: =IFERROR((F28/E28)*D28,"")
E29: =IFERROR(VLOOKUP(C29,'Registro de Insumos'!D:G,3,FALSE),"") | F29: =IFERROR(VLOOKUP(C29,'Registro de Insumos'!D:G,4,FALSE),"") | G29: =IFERROR((F29/E29)*D29,"")
E30: =IFERROR(VLOOKUP(C30,'Registro de Insumos'!D:G,3,FALSE),"") | F30: =IFERROR(VLOOKUP(C30,'Registro de Insumos'!D:G,4,FALSE),"") | G30: =IFERROR((F30/E30)*D30,"")
E31: =IFERROR(VLOOKUP(C31,'Registro de Insumos'!D:G,3,FALSE),"") | F31: =IFERROR(VLOOKUP(C31,'Registro de Insumos'!D:G,4,FALSE),"") | G31: =IFERROR((F31/E31)*D31,"")
E32: =IFERROR(VLOOKUP(C32,'Registro de Insumos'!D:G,3,FALSE),"") | F32: =IFERROR(VLOOKUP(C32,'Registro de Insumos'!D:G,4,FALSE),"") | G32: =IFERROR((F32/E32)*D32,"")
E33: =IFERROR(VLOOKUP(C33,'Registro de Insumos'!D:G,3,FALSE),"") | F33: =IFERROR(VLOOKUP(C33,'Registro de Insumos'!D:G,4,FALSE),"") | G33: =IFERROR((F33/E33)*D33,"")
E34: =IFERROR(VLOOKUP(C34,'Registro de Insumos'!D:G,3,FALSE),"") | F34: =IFERROR(VLOOKUP(C34,'Registro de Insumos'!D:G,4,FALSE),"") | G34: =IFERROR((F34/E34)*D34,"")
E35: =IFERROR(VLOOKUP(C35,'Registro de Insumos'!D:G,3,FALSE),"") | F35: =IFERROR(VLOOKUP(C35,'Registro de Insumos'!D:G,4,FALSE),"") | G35: =IFERROR((F35/E35)*D35,"")
E36: =IFERROR(VLOOKUP(C36,'Registro de Insumos'!D:G,3,FALSE),"") | F36: =IFERROR(VLOOKUP(C36,'Registro de Insumos'!D:G,4,FALSE),"") | G36: =IFERROR((F36/E36)*D36,"")
E37: =IFERROR(VLOOKUP(C37,'Registro de Insumos'!D:G,3,FALSE),"") | F37: =IFERROR(VLOOKUP(C37,'Registro de Insumos'!D:G,4,FALSE),"") | G37: =IFERROR((F37/E37)*D37,"")
E38: =IFERROR(VLOOKUP(C38,'Registro de Insumos'!D:G,3,FALSE),"") | F38: =IFERROR(VLOOKUP(C38,'Registro de Insumos'!D:G,4,FALSE),"") | G38: =IFERROR((F38/E38)*D38,"")
E39: =IFERROR(VLOOKUP(C39,'Registro de Insumos'!D:G,3,FALSE),"") | F39: =IFERROR(VLOOKUP(C39,'Registro de Insumos'!D:G,4,FALSE),"") | G39: =IFERROR((F39/E39)*D39,"")
... E101: =IFERROR(VLOOKUP(C101,'Registro de Insumos'!D:G,3,FALSE),"") | F101: =IFERROR(VLOOKUP(C101,'Registro de Insumos'!D:G,4,FALSE),"") | G101: =IFERROR((F101/E101)*D101,"")

Sheet Precificação Serviços | Custo D
B1: Preço de Venda de Serviço com Preço Desconhecido
A6: 0 | C6: SEERRO(FILTER( 'Base de Dados'!A7:Q; ('Base de Dados'!A7:A = C16) + (C16 = ""); ('Base de Dados'!E7:E = C17) + (C17 = ""); ('Base de Dados'!C7:C = C18) + (C18 = ""); ('Base de Dados'!I7:I = C19) + (C19 = ""); ('Base de Dados'!D7:D = C20) + (C20 = ""));) | D6: FILTER(A10:L14; (D10:D14 <> "") * (E10:E14 <> "") * (F10:F14 <> "") * (G10:G14 <> "") * (I10:I14 <> "") * (J10:J14 <> ""))
C7: Preenchimento de Insumos | I7: Informações Extras | L7: DRE do Projeto | N7: Individual | Q7: Lote
B9: Editar | C9: Nome do Item | D9: Quantidade | E9: Quantidade Referência | F9: Valor Referência | G9: Valor Custo | I9: Margem de Lucro | J9: Porcentagem | L9: DRE - Projeto | N9: Valor | O9: % do Preço | Q9: Valor | R9: % do Preço
B10: Registro | C10: Ovo | D10: 1 | E10: =IFERROR(VLOOKUP(C10,'Registro de Insumos'!D:G,3,FALSE),"") | F10: =IFERROR(VLOOKUP(C10,'Registro de Insumos'!D:G,4,FALSE),"") | G10: =IFERROR((F10/E10)*D10,"") | I10: Margem Desejada | J10: 0.1 | L10: Preço de Venda | N10: =J27 -> 0 | O10: =J14*J25/N10 -> #DIV/0! | Q10: 0.3 | R10: 0.3
E11: =IFERROR(VLOOKUP(C11,'Registro de Insumos'!D:G,3,FALSE),"") | F11: =IFERROR(VLOOKUP(C11,'Registro de Insumos'!D:G,4,FALSE),"") | G11: =IFERROR((F11/E11)*D11,"")
E12: =IFERROR(VLOOKUP(C12,'Registro de Insumos'!D:G,3,FALSE),"") | F12: =IFERROR(VLOOKUP(C12,'Registro de Insumos'!D:G,4,FALSE),"") | G12: =IFERROR((F12/E12)*D12,"") | I12: Unidades desse Lote | J12: Quantidade Unitária | L12: =#REF! -> #REF! | N12: =IFERROR(O12*$N$10,"") -> 0 | O12: =IFERROR(VLOOKUP(L12,'Gastos Variáveis'!D:E,2,FALSE),"") | Q12: =#REF! -> #REF! | R12: =#REF! -> #REF!
E13: =IFERROR(VLOOKUP(C13,'Registro de Insumos'!D:G,3,FALSE),"") | F13: =IFERROR(VLOOKUP(C13,'Registro de Insumos'!D:G,4,FALSE),"") | G13: =IFERROR((F13/E13)*D13,"") | I13: Quantidade Produzida | J13: 10 | L13: =#REF! -> #REF! | N13: =IFERROR(O13*$N$10,"") -> 0 | O13: =IFERROR(VLOOKUP(L13,'Gastos Variáveis'!D:E,2,FALSE),"") | Q13: =#REF! -> #REF! | R13: =#REF! -> #REF!
E14: =IFERROR(VLOOKUP(C14,'Registro de Insumos'!D:G,3,FALSE),"") | F14: =IFERROR(VLOOKUP(C14,'Registro de Insumos'!D:G,4,FALSE),"") | G14: =IFERROR((F14/E14)*D14,"") | I14: Custo Unitário | J14: =(SUM(G10:G9999))/J13 -> 0 | L14: =#REF! -> #REF! | N14: =IFERROR(O14*$N$10,"") -> 0 | O14: =IFERROR(VLOOKUP(L14,'Gastos Variáveis'!D:E,2,FALSE),"") | Q14: =#REF! -> #REF! | R14: =#REF! -> #REF!
E15: =IFERROR(VLOOKUP(C15,'Registro de Insumos'!D:G,3,FALSE),"") | F15: =IFERROR(VLOOKUP(C15,'Registro de Insumos'!D:G,4,FALSE),"") | G15: =IFERROR((F15/E15)*D15,"") | L15: ='Gastos Variáveis'!D14 -> Impostos | N15: =IFERROR(O15*$N$10,"") -> 0 | O15: =IFERROR(VLOOKUP(L15,'Gastos Variáveis'!D:E,2,FALSE),"") -> 0.0094 | Q15: ='Gastos Variáveis'!I14 | R15: ='Gastos Variáveis'!J14
E16: =IFERROR(VLOOKUP(C16,'Registro de Insumos'!D:G,3,FALSE),"") | F16: =IFERROR(VLOOKUP(C16,'Registro de Insumos'!D:G,4,FALSE),"") | G16: =IFERROR((F16/E16)*D16,"") | N16: =IFERROR(O16*$N$10,"") -> 0 | O16: =IFERROR(VLOOKUP(L16,'Gastos Variáveis'!D:E,2,FALSE),"") | Q16: ='Gastos Variáveis'!I15 | R16: ='Gastos Variáveis'!J15
E17: =IFERROR(VLOOKUP(C17,'Registro de Insumos'!D:G,3,FALSE),"") | F17: =IFERROR(VLOOKUP(C17,'Registro de Insumos'!D:G,4,FALSE),"") | G17: =IFERROR((F17/E17)*D17,"") | I17: Precificação do Produto | L17: ='Gastos Variáveis'!D16 | N17: =IFERROR(O17*$N$10,"") -> 0 | O17: =IFERROR(VLOOKUP(L17,'Gastos Variáveis'!D:E,2,FALSE),"") | Q17: ='Gastos Variáveis'!I16 | R17: ='Gastos Variáveis'!J16
E18: =IFERROR(VLOOKUP(C18,'Registro de Insumos'!D:G,3,FALSE),"") | F18: =IFERROR(VLOOKUP(C18,'Registro de Insumos'!D:G,4,FALSE),"") | G18: =IFERROR((F18/E18)*D18,"") | H18: Horas trabalhadas p/ mês | L18: ='Gastos Variáveis'!D17 | N18: =IFERROR(O18*$N$10,"") -> 0 | O18: =IFERROR(VLOOKUP(L18,'Gastos Variáveis'!D:E,2,FALSE),"") | Q18: ='Gastos Variáveis'!I17 | R18: ='Gastos Variáveis'!J17
E19: =IFERROR(VLOOKUP(C19,'Registro de Insumos'!D:G,3,FALSE),"") | F19: =IFERROR(VLOOKUP(C19,'Registro de Insumos'!D:G,4,FALSE),"") | G19: =IFERROR((F19/E19)*D19,"") | H19: 160 | I19: Informações | J19: Valor | L19: ='Gastos Variáveis'!D18 | N19: =IFERROR(O19*$N$10,"") -> 0 | O19: =IFERROR(VLOOKUP(L19,'Gastos Variáveis'!D:E,2,FALSE),"") | Q19: ='Gastos Variáveis'!I18 | R19: ='Gastos Variáveis'!J18
E20: =IFERROR(VLOOKUP(C20,'Registro de Insumos'!D:G,3,FALSE),"") | F20: =IFERROR(VLOOKUP(C20,'Registro de Insumos'!D:G,4,FALSE),"") | G20: =IFERROR((F20/E20)*D20,"") | H20: 176 | I20: Custo Fixo | J20: ='Gastos Fixos'!H11 -> 0.20082555 | L20: Total Custos Variáveis | N20: 0.3 | O20: 0.3 | Q20: 0.3 | R20: 0.3
E21: =IFERROR(VLOOKUP(C21,'Registro de Insumos'!D:G,3,FALSE),"") | F21: =IFERROR(VLOOKUP(C21,'Registro de Insumos'!D:G,4,FALSE),"") | G21: =IFERROR((F21/E21)*D21,"") | H21: 176 | I21: Custo Variável | J21: ='Gastos Variáveis'!H9 -> 0.0094 | L21: Total Custos Fixos | N21: 0.3 | O21: 0.3 | Q21: 0.3 | R21: 0.3
E22: =IFERROR(VLOOKUP(C22,'Registro de Insumos'!D:G,3,FALSE),"") | F22: =IFERROR(VLOOKUP(C22,'Registro de Insumos'!D:G,4,FALSE),"") | G22: =IFERROR((F22/E22)*D22,"") | I22: Margem | J22: =J10 -> 0.1 | L22: Custo do Produto | N22: 0.3 | O22: 0.3 | Q22: 0.3 | R22: 0.3
E23: =IFERROR(VLOOKUP(C23,'Registro de Insumos'!D:G,3,FALSE),"") | F23: =IFERROR(VLOOKUP(C23,'Registro de Insumos'!D:G,4,FALSE),"") | G23: =IFERROR((F23/E23)*D23,"") | I23: Salários | J23: ='Base de Salários'!J14 -> 0.0084433977 | L23: Total de Custos | N23: 0.3 | O23: 0.3 | Q23: 0.3 | R23: 0.3
E24: =IFERROR(VLOOKUP(C24,'Registro de Insumos'!D:G,3,FALSE),"") | F24: =IFERROR(VLOOKUP(C24,'Registro de Insumos'!D:G,4,FALSE),"") | G24: =IFERROR((F24/E24)*D24,"") | I24: Soma | J24: =SUM(J20:J23) -> 0.31866895
E25: =IFERROR(VLOOKUP(C25,'Registro de Insumos'!D:G,3,FALSE),"") | F25: =IFERROR(VLOOKUP(C25,'Registro de Insumos'!D:G,4,FALSE),"") | G25: =IFERROR((F25/E25)*D25,"") | I25: Markup | J25: =1/(1-(J20+J21+J22+J23)) -> 1.4677153 | L25: Margem de Lucro | N25: 0.3 | O25: 0.3 | Q25: 0.3 | R25: 0.3
E26: =IFERROR(VLOOKUP(C26,'Registro de Insumos'!D:G,3,FALSE),"") | F26: =IFERROR(VLOOKUP(C26,'Registro de Insumos'!D:G,4,FALSE),"") | G26: =IFERROR((F26/E26)*D26,"")
